Traceback (most recent call last):
  File "/home/codespace/.local/lib/python3.12/site-packages/jupyter_core/utils/__init__.py", line 154, in wrapped
    asyncio.get_running_loop()
RuntimeError: no running event loop

During handling of the above exception, another exception occurred:

Traceback (most recent call last):
  File "/usr/local/python/3.12.1/lib/python3.12/site-packages/jupyter_cache/executors/utils.py", line 58, in single_nb_execution
    executenb(
  File "/home/codespace/.local/lib/python3.12/site-packages/nbclient/client.py", line 1319, in execute
    return NotebookClient(nb=nb, resources=resources, km=km, **kwargs).execute()
           ^^^^^^^^^^^^^^^^^^^^^^^^^^^^^^^^^^^^^^^^^^^^^^^^^^^^^^^^^^^^^^^^^^^^^
  File "/home/codespace/.local/lib/python3.12/site-packages/jupyter_core/utils/__init__.py", line 158, in wrapped
    return loop.run_until_complete(inner)
           ^^^^^^^^^^^^^^^^^^^^^^^^^^^^^^
  File "/usr/local/python/3.12.1/lib/python3.12/asyncio/base_events.py", line 684, in run_until_complete
    return future.result()
           ^^^^^^^^^^^^^^^
  File "/home/codespace/.local/lib/python3.12/site-packages/nbclient/client.py", line 709, in async_execute
    await self.async_execute_cell(
  File "/home/codespace/.local/lib/python3.12/site-packages/nbclient/client.py", line 1062, in async_execute_cell
    await self._check_raise_for_error(cell, cell_index, exec_reply)
  File "/home/codespace/.local/lib/python3.12/site-packages/nbclient/client.py", line 918, in _check_raise_for_error
    raise CellExecutionError.from_cell_and_msg(cell, exec_reply_content)
nbclient.exceptions.CellExecutionError: An error occurred while executing the following cell:
------------------
import matplotlib.pyplot as plt
import matplotlib.image as mpimg

# Path gambar kamu
img_path = r"D:\OneDrive\Pictures\Screenshots\koordinat_kamal.png"

# Baca dan tampilkan
img = mpimg.imread(img_path)
plt.imshow(img)
plt.axis('off') 
plt.show()
------------------


[31m---------------------------------------------------------------------------[39m
[31mFileNotFoundError[39m                         Traceback (most recent call last)
[36mCell[39m[36m [39m[32mIn[1][39m[32m, line 8[39m
[32m      5[39m img_path = [33mr[39m[33m"[39m[33mD:[39m[33m\[39m[33mOneDrive[39m[33m\[39m[33mPictures[39m[33m\[39m[33mScreenshots[39m[33m\[39m[33mkoordinat_kamal.png[39m[33m"[39m
[32m      7[39m [38;5;66;03m# Baca dan tampilkan[39;00m
[32m----> [39m[32m8[39m img = [43mmpimg[49m[43m.[49m[43mimread[49m[43m([49m[43mimg_path[49m[43m)[49m
[32m      9[39m plt.imshow(img)
[32m     10[39m plt.axis([33m'[39m[33moff[39m[33m'[39m) 

[36mFile [39m[32m~/.local/lib/python3.12/site-packages/matplotlib/image.py:1520[39m, in [36mimread[39m[34m(fname, format)[39m
[32m   1513[39m [38;5;28;01mif[39;00m [38;5;28misinstance[39m(fname, [38;5;28mstr[39m) [38;5;129;01mand[39;00m [38;5;28mlen[39m(parse.urlparse(fname).scheme) > [32m1[39m:
[32m   1514[39m     [38;5;66;03m# Pillow doesn't handle URLs directly.[39;00m
[32m   1515[39m     [38;5;28;01mraise[39;00m [38;5;167;01mValueError[39;00m(
[32m   1516[39m         [33m"[39m[33mPlease open the URL for reading and pass the [39m[33m"[39m
[32m   1517[39m         [33m"[39m[33mresult to Pillow, e.g. with [39m[33m"[39m
[32m   1518[39m         [33m"[39m[33m``np.array(PIL.Image.open(urllib.request.urlopen(url)))``.[39m[33m"[39m
[32m   1519[39m         )
[32m-> [39m[32m1520[39m [38;5;28;01mwith[39;00m [43mimg_open[49m[43m([49m[43mfname[49m[43m)[49m [38;5;28;01mas[39;00m image:
[32m   1521[39m     [38;5;28;01mreturn[39;00m (_pil_png_to_float_array(image)
[32m   1522[39m             [38;5;28;01mif[39;00m [38;5;28misinstance[39m(image, PIL.PngImagePlugin.PngImageFile) [38;5;28;01melse[39;00m
[32m   1523[39m             pil_to_array(image))

[36mFile [39m[32m~/.local/lib/python3.12/site-packages/PIL/ImageFile.py:135[39m, in [36mImageFile.__init__[39m[34m(self, fp, filename)[39m
[32m    131[39m [38;5;28mself[39m.decodermaxblock = MAXBLOCK
[32m    133[39m [38;5;28;01mif[39;00m is_path(fp):
[32m    134[39m     [38;5;66;03m# filename[39;00m
[32m--> [39m[32m135[39m     [38;5;28mself[39m.fp = [38;5;28;43mopen[39;49m[43m([49m[43mfp[49m[43m,[49m[43m [49m[33;43m"[39;49m[33;43mrb[39;49m[33;43m"[39;49m[43m)[49m
[32m    136[39m     [38;5;28mself[39m.filename = os.fspath(fp)
[32m    137[39m     [38;5;28mself[39m._exclusive_fp = [38;5;28;01mTrue[39;00m

[31mFileNotFoundError[39m: [Errno 2] No such file or directory: 'D:\\OneDrive\\Pictures\\Screenshots\\koordinat_kamal.png'

